<sdf version='1.6'>
  <world name='default'>
    <plugin name='ros_link_attacher_plugin' filename='libgazebo_ros_link_attacher.so'/>
    <light name='sun' type='directional'>
      <cast_shadows>1</cast_shadows>
      <pose frame=''>0 0 10 0 -0 0</pose>
      <diffuse>0.8 0.8 0.8 1</diffuse>
      <specular>0.2 0.2 0.2 1</specular>
      <attenuation>
        <range>1000</range>
        <constant>0.9</constant>
        <linear>0.01</linear>
        <quadratic>0.001</quadratic>
      </attenuation>
      <direction>-0.5 0.1 -0.9</direction>
    </light>
    <physics name='default_physics' default='0' type='ode'>
      <ode>
        <solver>
          <type>quick</type>
          <iters>10</iters>
          <sor>1.3</sor>
          <use_dynamic_moi_rescaling>0</use_dynamic_moi_rescaling>
        </solver>
        <constraints>
          <cfm>0</cfm>
          <erp>0.2</erp>
          <contact_max_correcting_vel>100</contact_max_correcting_vel>
          <contact_surface_layer>0.001</contact_surface_layer>
        </constraints>
      </ode>
      <max_step_size>0.004</max_step_size>
      <real_time_factor>1</real_time_factor>
      <real_time_update_rate>250</real_time_update_rate>
    </physics>
    <gravity>0 0 -9.8066</gravity>
    <magnetic_field>6e-06 2.3e-05 -4.2e-05</magnetic_field>
    <atmosphere type='adiabatic'/>
    <scene>
      <ambient>0.4 0.4 0.4 1</ambient>
      <background>0.7 0.7 0.7 1</background>
      <shadows>1</shadows>
    </scene>
    <spherical_coordinates>
      <surface_model>EARTH_WGS84</surface_model>
      <latitude_deg>0</latitude_deg>
      <longitude_deg>0</longitude_deg>
      <elevation>0</elevation>
      <heading_deg>0</heading_deg>
    </spherical_coordinates>
    <model name='bishop-terrain'>
      <static>1</static>
      <link name='link'>
        <collision name='collision'>
          <geometry>
            <mesh>
              <uri>model://bishop-terrain/meshes/bishop-sep-2019.obj</uri>
            </mesh>
          </geometry>
          <max_contacts>10</max_contacts>
          <surface>
            <contact>
              <ode/>
            </contact>
            <bounce/>
            <friction>
              <torsional>
                <ode/>
              </torsional>
              <ode/>
            </friction>
          </surface>
        </collision>
        <visual name='visual'>
          <geometry>
            <mesh>
              <uri>model://bishop-terrain/meshes/bishop-sep-2019.obj</uri>
            </mesh>
          </geometry>
          <material>
            <ambient>0.5 0.5 0.5 1</ambient>
            <diffuse>0.9 0.49 0.06 1</diffuse>
            <specular>0 0 0 0</specular>
            <emissive>0 0 0 1</emissive>
          </material>
        </visual>
        <self_collide>0</self_collide>
        <kinematic>0</kinematic>
      </link>
    </model>
    <model name='cps_rover'>
      <static>1</static>
      <link name='base_link'>
        <inertial>
          <mass>720</mass>
          <inertia>
            <ixx>140</ixx>
            <ixy>0</ixy>
            <iyy>550</iyy>
            <ixz>0</ixz>
            <iyz>0</iyz>
            <izz>550</izz>
          </inertia>
          <pose frame=''>0.1 0 0.4 0 -0 0</pose>
        </inertial>
        <visual name='visual'>
          <pose frame=''>0 0 0 0 0 -1.5708</pose>
          <geometry>
            <mesh>
              <uri>model://rover/meshes/polaris.dae</uri>
              <submesh>
                <name>Body</name>
                <center>0</center>
              </submesh>
            </mesh>
          </geometry>
          <material>
            <script>
              <uri>model://rover/materials/scripts</uri>
              <uri>model://rover/materials/textures</uri>
              <name>PolarisXP900/Diffuse</name>
            </script>
          </material>
        </visual>
        <collision name='base_link_bottom'>
          <pose frame=''>0.2 0 0.335 0 -0 0</pose>
          <geometry>
            <box>
              <size>1.34 1.65746 0.06</size>
            </box>
          </geometry>
          <max_contacts>10</max_contacts>
          <surface>
            <contact>
              <ode/>
            </contact>
            <bounce/>
            <friction>
              <torsional>
                <ode/>
              </torsional>
              <ode/>
            </friction>
          </surface>
        </collision>
        <collision name='cargo_bottom'>
          <pose frame=''>-1 0 0.921 0 -0 0</pose>
          <geometry>
            <box>
              <size>1.04609 1.6998 0.01</size>
            </box>
          </geometry>
          <max_contacts>10</max_contacts>
          <surface>
            <contact>
              <ode/>
            </contact>
            <bounce/>
            <friction>
              <torsional>
                <ode/>
              </torsional>
              <ode/>
            </friction>
          </surface>
        </collision>
        <collision name='cargo_front'>
          <pose frame=''>-0.495 0 1.06 0 -0 0</pose>
          <geometry>
            <box>
              <size>0.05 1.69982 0.27</size>
            </box>
          </geometry>
          <max_contacts>10</max_contacts>
          <surface>
            <contact>
              <ode/>
            </contact>
            <bounce/>
            <friction>
              <torsional>
                <ode/>
              </torsional>
              <ode/>
            </friction>
          </surface>
        </collision>
        <collision name='cargo_back'>
          <pose frame=''>-1.465 0 1.06 0 -0 0</pose>
          <geometry>
            <box>
              <size>0.05 1.69982 0.27</size>
            </box>
          </geometry>
          <max_contacts>10</max_contacts>
          <surface>
            <contact>
              <ode/>
            </contact>
            <bounce/>
            <friction>
              <torsional>
                <ode/>
              </torsional>
              <ode/>
            </friction>
          </surface>
        </collision>
        <collision name='cargo_left'>
          <pose frame=''>-0.97 0.82491 1.06 0 -0 0</pose>
          <geometry>
            <box>
              <size>1.04609 0.05 0.27</size>
            </box>
          </geometry>
          <max_contacts>10</max_contacts>
          <surface>
            <contact>
              <ode/>
            </contact>
            <bounce/>
            <friction>
              <torsional>
                <ode/>
              </torsional>
              <ode/>
            </friction>
          </surface>
        </collision>
        <collision name='cargo_right'>
          <pose frame=''>-0.97 -0.82491 1.06 0 -0 0</pose>
          <geometry>
            <box>
              <size>1.04609 0.05 0.27</size>
            </box>
          </geometry>
          <max_contacts>10</max_contacts>
          <surface>
            <contact>
              <ode/>
            </contact>
            <bounce/>
            <friction>
              <torsional>
                <ode/>
              </torsional>
              <ode/>
            </friction>
          </surface>
        </collision>
        <collision name='seat'>
          <pose frame=''>0 0 0.62 0 -0 0</pose>
          <geometry>
            <box>
              <size>0.52167 1.37206 0.53369</size>
            </box>
          </geometry>
          <surface>
            <contact>
              <ode>
                <min_depth>0.01</min_depth>
              </ode>
            </contact>
            <bounce/>
            <friction>
              <torsional>
                <ode/>
              </torsional>
              <ode/>
            </friction>
          </surface>
          <max_contacts>10</max_contacts>
        </collision>
        <collision name='mud_seat'>
          <pose frame=''>0 0 0.86 0 -0 0</pose>
          <geometry>
            <box>
              <size>0.52167 1.3 0.1</size>
            </box>
          </geometry>
          <surface>
            <contact>
              <collide_without_contact>1</collide_without_contact>
              <ode/>
            </contact>
            <bounce/>
            <friction>
              <torsional>
                <ode/>
              </torsional>
              <ode/>
            </friction>
          </surface>
          <max_contacts>10</max_contacts>
        </collision>
        <sensor name='seat_contact' type='contact'>
          <always_on>1</always_on>
          <update_rate>1000</update_rate>
          <contact>
            <collision>mud_seat</collision>
            <topic>__default_topic__</topic>
          </contact>
        </sensor>
        <collision name='seat_back'>
          <pose frame=''>-0.26 0 1.125 0 -0.2 0</pose>
          <geometry>
            <box>
              <size>0.06 1.37206 0.6</size>
            </box>
          </geometry>
          <max_contacts>10</max_contacts>
          <surface>
            <contact>
              <ode/>
            </contact>
            <bounce/>
            <friction>
              <torsional>
                <ode/>
              </torsional>
              <ode/>
            </friction>
          </surface>
        </collision>
        <collision name='engine'>
          <pose frame=''>1.12 0 0.7 0 -0 0</pose>
          <geometry>
            <box>
              <size>0.58 1.3 0.8</size>
            </box>
          </geometry>
          <max_contacts>10</max_contacts>
          <surface>
            <contact>
              <ode/>
            </contact>
            <bounce/>
            <friction>
              <torsional>
                <ode/>
              </torsional>
              <ode/>
            </friction>
          </surface>
        </collision>
        <collision name='rollcage_top_left'>
          <pose frame=''>-0.02 0.76 1.936 3.14159 1.54159 3.14159</pose>
          <geometry>
            <cylinder>
              <radius>0.03</radius>
              <length>0.68</length>
            </cylinder>
          </geometry>
          <max_contacts>10</max_contacts>
          <surface>
            <contact>
              <ode/>
            </contact>
            <bounce/>
            <friction>
              <torsional>
                <ode/>
              </torsional>
              <ode/>
            </friction>
          </surface>
        </collision>
        <collision name='rollcage_top_right'>
          <pose frame=''>-0.02 -0.76 1.936 3.14159 1.54159 3.14159</pose>
          <geometry>
            <cylinder>
              <radius>0.03</radius>
              <length>0.68</length>
            </cylinder>
          </geometry>
          <max_contacts>10</max_contacts>
          <surface>
            <contact>
              <ode/>
            </contact>
            <bounce/>
            <friction>
              <torsional>
                <ode/>
              </torsional>
              <ode/>
            </friction>
          </surface>
        </collision>
        <collision name='rollcage_top_front'>
          <pose frame=''>0.315 0 1.93 0 -1 0</pose>
          <geometry>
            <box>
              <size>0.01299 1.54 0.10226</size>
            </box>
          </geometry>
          <max_contacts>10</max_contacts>
          <surface>
            <contact>
              <ode/>
            </contact>
            <bounce/>
            <friction>
              <torsional>
                <ode/>
              </torsional>
              <ode/>
            </friction>
          </surface>
        </collision>
        <collision name='rollcage_top_back'>
          <pose frame=''>-0.41 0 1.88 0 -0 0</pose>
          <geometry>
            <box>
              <size>0.01299 1.54 0.10226</size>
            </box>
          </geometry>
          <max_contacts>10</max_contacts>
          <surface>
            <contact>
              <ode/>
            </contact>
            <bounce/>
            <friction>
              <torsional>
                <ode/>
              </torsional>
              <ode/>
            </friction>
          </surface>
        </collision>
        <collision name='rollcage_front_left'>
          <pose frame=''>0.602 0.755 1.45 0 -0.54 0</pose>
          <geometry>
            <cylinder>
              <radius>0.03</radius>
              <length>1.15</length>
            </cylinder>
          </geometry>
          <max_contacts>10</max_contacts>
          <surface>
            <contact>
              <ode/>
            </contact>
            <bounce/>
            <friction>
              <torsional>
                <ode/>
              </torsional>
              <ode/>
            </friction>
          </surface>
        </collision>
        <collision name='rollcage_front_right'>
          <pose frame=''>0.602 -0.755 1.45 0 -0.54 0</pose>
          <geometry>
            <cylinder>
              <radius>0.03</radius>
              <length>1.15</length>
            </cylinder>
          </geometry>
          <max_contacts>10</max_contacts>
          <surface>
            <contact>
              <ode/>
            </contact>
            <bounce/>
            <friction>
              <torsional>
                <ode/>
              </torsional>
              <ode/>
            </friction>
          </surface>
        </collision>
        <collision name='rollcage_back_left'>
          <pose frame=''>-0.4 0.755 1.45 0 -0 0</pose>
          <geometry>
            <cylinder>
              <radius>0.03</radius>
              <length>1</length>
            </cylinder>
          </geometry>
          <max_contacts>10</max_contacts>
          <surface>
            <contact>
              <ode/>
            </contact>
            <bounce/>
            <friction>
              <torsional>
                <ode/>
              </torsional>
              <ode/>
            </friction>
          </surface>
        </collision>
        <collision name='rollcage_back_right'>
          <pose frame=''>-0.4 -0.755 1.45 0 -0 0</pose>
          <geometry>
            <cylinder>
              <radius>0.03</radius>
              <length>1</length>
            </cylinder>
          </geometry>
          <max_contacts>10</max_contacts>
          <surface>
            <contact>
              <ode/>
            </contact>
            <bounce/>
            <friction>
              <torsional>
                <ode/>
              </torsional>
              <ode/>
            </friction>
          </surface>
        </collision>
        <collision name='rollcage_X_1'>
          <pose frame=''>-0.411 0.04 1.445 0.397 -0 0</pose>
          <geometry>
            <box>
              <size>0.01392 1.55724 0.078</size>
            </box>
          </geometry>
          <max_contacts>10</max_contacts>
          <surface>
            <contact>
              <ode/>
            </contact>
            <bounce/>
            <friction>
              <torsional>
                <ode/>
              </torsional>
              <ode/>
            </friction>
          </surface>
        </collision>
        <collision name='rollcage_X_2'>
          <pose frame=''>-0.4 -0.04 1.445 -0.397 0 0</pose>
          <geometry>
            <box>
              <size>0.01392 1.55724 0.078</size>
            </box>
          </geometry>
          <max_contacts>10</max_contacts>
          <surface>
            <contact>
              <ode/>
            </contact>
            <bounce/>
            <friction>
              <torsional>
                <ode/>
              </torsional>
              <ode/>
            </friction>
          </surface>
        </collision>
        <collision name='central_hump1_collision'>
          <pose frame=''>0.55 -0.1 0.4 0 -0 0</pose>
          <geometry>
            <box>
              <size>0.6 0.15 0.1</size>
            </box>
          </geometry>
          <max_contacts>10</max_contacts>
          <surface>
            <contact>
              <ode/>
            </contact>
            <bounce/>
            <friction>
              <torsional>
                <ode/>
              </torsional>
              <ode/>
            </friction>
          </surface>
        </collision>
        <collision name='central_hump2_collision'>
          <pose frame=''>0.7 -0.05 0.45 0 -0.5 0</pose>
          <geometry>
            <box>
              <size>0.2 0.05 0.1</size>
            </box>
          </geometry>
          <max_contacts>10</max_contacts>
          <surface>
            <contact>
              <ode/>
            </contact>
            <bounce/>
            <friction>
              <torsional>
                <ode/>
              </torsional>
              <ode/>
            </friction>
          </surface>
        </collision>
        <collision name='central_hump3_collision'>
          <pose frame=''>0.798 -0.125 0.478 0 -0.8 0</pose>
          <geometry>
            <box>
              <size>0.129 0.1 0.05</size>
            </box>
          </geometry>
          <max_contacts>10</max_contacts>
          <surface>
            <contact>
              <ode/>
            </contact>
            <bounce/>
            <friction>
              <torsional>
                <ode/>
              </torsional>
              <ode/>
            </friction>
          </surface>
        </collision>
        <collision name='central_hump4_collision'>
          <pose frame=''>0.8135 -0.05 0.45 0 -0 0</pose>
          <geometry>
            <box>
              <size>0.1 0.05 0.1835</size>
            </box>
          </geometry>
          <max_contacts>10</max_contacts>
          <surface>
            <contact>
              <ode/>
            </contact>
            <bounce/>
            <friction>
              <torsional>
                <ode/>
              </torsional>
              <ode/>
            </friction>
          </surface>
        </collision>
        <collision name='central_hump5_collision'>
          <pose frame=''>0.84 -0.125 0.45 0 -0 0</pose>
          <geometry>
            <box>
              <size>0.03 0.1 0.1835</size>
            </box>
          </geometry>
          <max_contacts>10</max_contacts>
          <surface>
            <contact>
              <ode/>
            </contact>
            <bounce/>
            <friction>
              <torsional>
                <ode/>
              </torsional>
              <ode/>
            </friction>
          </surface>
        </collision>
        <collision name='central_hump6_collision'>
          <pose frame=''>0.82 -0.125 0.475 0 -0 0</pose>
          <geometry>
            <box>
              <size>0.03 0.1 0.05</size>
            </box>
          </geometry>
          <max_contacts>10</max_contacts>
          <surface>
            <contact>
              <ode/>
            </contact>
            <bounce/>
            <friction>
              <torsional>
                <ode/>
              </torsional>
              <ode/>
            </friction>
          </surface>
        </collision>
        <visual name='cargo_visual'>
          <pose frame=''>-1 0 1.0323 0 0 -1.5707</pose>
          <geometry>
            <mesh>
              <uri>model://rover/meshes/polaris.dae</uri>
              <submesh>
                <name>Bed</name>
                <center>1</center>
              </submesh>
            </mesh>
          </geometry>
          <material>
            <script>
              <uri>model://rover/materials/scripts</uri>
              <uri>model://rover/materials/textures</uri>
              <name>PolarisXP900/Diffuse</name>
            </script>
          </material>
        </visual>
        <visual name='tailgate_visual'>
          <pose frame=''>-1.492 0 1.03 0 0 -1.5707</pose>
          <geometry>
            <mesh>
              <uri>model://rover/meshes/polaris.dae</uri>
              <submesh>
                <name>Tail_Gate</name>
                <center>1</center>
              </submesh>
            </mesh>
          </geometry>
          <material>
            <script>
              <uri>model://rover/materials/scripts</uri>
              <uri>model://rover/materials/textures</uri>
              <name>PolarisXP900/Diffuse</name>
            </script>
          </material>
        </visual>
        <visual name='front_left_brake_visual'>
          <pose frame=''>1.12 -0.57488 0.35516 3.1415 -0 1.5707</pose>
          <geometry>
            <mesh>
              <uri>model://rover/meshes/polaris.dae</uri>
              <submesh>
                <name>Brake_Front_Left</name>
                <center>1</center>
              </submesh>
            </mesh>
          </geometry>
          <material>
            <script>
              <uri>model://rover/materials/scripts</uri>
              <uri>model://rover/materials/textures</uri>
              <name>PolarisXP900/Diffuse</name>
            </script>
          </material>
        </visual>
        <visual name='front_right_brake_visual'>
          <pose frame=''>1.12 0.57488 0.35516 3.1415 -0 1.5707</pose>
          <geometry>
            <mesh>
              <uri>model://rover/meshes/polaris.dae</uri>
              <submesh>
                <name>Brake_Front_Right</name>
                <center>1</center>
              </submesh>
            </mesh>
          </geometry>
          <material>
            <script>
              <uri>model://rover/materials/scripts</uri>
              <uri>model://rover/materials/textures</uri>
              <name>PolarisXP900/Diffuse</name>
            </script>
          </material>
        </visual>
        <visual name='central_hump1'>
          <pose frame=''>0.55 -0.1 0.4 0 -0 0</pose>
          <geometry>
            <box>
              <size>0.6 0.15 0.1</size>
            </box>
          </geometry>
          <material>
            <script>
              <uri>file://media/materials/scripts/gazebo.material</uri>
              <name>Gazebo/DarkGrey</name>
            </script>
          </material>
        </visual>
        <visual name='central_hump2'>
          <pose frame=''>0.7 -0.05 0.45 0 -0.5 0</pose>
          <geometry>
            <box>
              <size>0.2 0.05 0.1</size>
            </box>
          </geometry>
          <material>
            <script>
              <uri>file://media/materials/scripts/gazebo.material</uri>
              <name>Gazebo/DarkGrey</name>
            </script>
          </material>
        </visual>
        <visual name='central_hump3'>
          <pose frame=''>0.798 -0.125 0.478 0 -0.8 0</pose>
          <geometry>
            <box>
              <size>0.129 0.1 0.05</size>
            </box>
          </geometry>
          <material>
            <script>
              <uri>file://media/materials/scripts/gazebo.material</uri>
              <name>Gazebo/DarkGrey</name>
            </script>
          </material>
        </visual>
        <visual name='central_hump4'>
          <pose frame=''>0.8135 -0.05 0.45 0 -0 0</pose>
          <geometry>
            <box>
              <size>0.1 0.05 0.1835</size>
            </box>
          </geometry>
          <material>
            <script>
              <uri>file://media/materials/scripts/gazebo.material</uri>
              <name>Gazebo/DarkGrey</name>
            </script>
          </material>
        </visual>
        <visual name='central_hump5'>
          <pose frame=''>0.84 -0.125 0.45 0 -0 0</pose>
          <geometry>
            <box>
              <size>0.03 0.1 0.1835</size>
            </box>
          </geometry>
          <material>
            <script>
              <uri>file://media/materials/scripts/gazebo.material</uri>
              <name>Gazebo/DarkGrey</name>
            </script>
          </material>
        </visual>
        <visual name='central_hump6'>
          <pose frame=''>0.82 -0.125 0.475 0 -0 0</pose>
          <geometry>
            <box>
              <size>0.03 0.1 0.05</size>
            </box>
          </geometry>
          <material>
            <script>
              <uri>file://media/materials/scripts/gazebo.material</uri>
              <name>Gazebo/DarkGrey</name>
            </script>
          </material>
        </visual>
        <self_collide>0</self_collide>
        <kinematic>0</kinematic>
      </link>
      <link name='rover/imu_link'>
        <pose frame=''>0 0 0 0 -0 0</pose>
        <inertial>
          <pose frame=''>0 0 0 0 -0 0</pose>
          <mass>0.015</mass>
          <inertia>
            <ixx>1e-05</ixx>
            <ixy>0</ixy>
            <ixz>0</ixz>
            <iyy>1e-05</iyy>
            <iyz>0</iyz>
            <izz>1e-05</izz>
          </inertia>
        </inertial>
        <self_collide>0</self_collide>
        <kinematic>0</kinematic>
      </link>
      <joint name='rover/imu_joint' type='revolute'>
        <child>rover/imu_link</child>
        <parent>base_link</parent>
        <axis>
          <xyz>1 0 0</xyz>
          <limit>
            <lower>0</lower>
            <upper>0</upper>
            <effort>0</effort>
            <velocity>0</velocity>
          </limit>
          <dynamics>
            <spring_reference>0</spring_reference>
            <spring_stiffness>0</spring_stiffness>
          </dynamics>
          <use_parent_model_frame>1</use_parent_model_frame>
        </axis>
      </joint>
      <link name='front_left_wheel'>
        <pose frame=''>1.20223 0.71562 0.34697 -1.52 0 0</pose>
        <inertial>
          <mass>12</mass>
          <inertia>
            <ixx>0.5</ixx>
            <ixy>0</ixy>
            <iyy>0.5</iyy>
            <ixz>0</ixz>
            <iyz>0</iyz>
            <izz>1</izz>
          </inertia>
        </inertial>
        <collision name='collision'>
          <geometry>
            <cylinder>
              <radius>0.3175</radius>
              <length>0.2794</length>
            </cylinder>
          </geometry>
          <max_contacts>1</max_contacts>
          <surface>
            <friction>
              <ode>
                <mu>1</mu>
                <mu2>1</mu2>
                <fdir1>0 0 1</fdir1>
                <slip1>0</slip1>
                <slip2>0</slip2>
              </ode>
              <torsional>
                <ode/>
              </torsional>
            </friction>
            <contact>
              <ode>
                <min_depth>0.005</min_depth>
                <kp>1e+08</kp>
              </ode>
            </contact>
            <bounce/>
          </surface>
        </collision>
        <visual name='tire_visual'>
          <pose frame=''>0 0 0 -3e-06 1.57079 3.14159</pose>
          <geometry>
            <mesh>
              <uri>model://rover/meshes/polaris.dae</uri>
              <scale>1.0037 0.8862 0.8862</scale>
              <submesh>
                <name>Wheel_Front_Left</name>
                <center>1</center>
              </submesh>
            </mesh>
          </geometry>
          <material>
            <script>
              <uri>model://rover/materials/scripts</uri>
              <uri>model://rover/materials/textures</uri>
              <name>PolarisXP900/Diffuse</name>
            </script>
          </material>
        </visual>
        <self_collide>0</self_collide>
        <kinematic>0</kinematic>
      </link>
      <link name='front_right_wheel'>
        <pose frame=''>1.20223 -0.71562 0.34697 1.52 -0 0</pose>
        <inertial>
          <mass>12</mass>
          <inertia>
            <ixx>0.5</ixx>
            <ixy>0</ixy>
            <iyy>0.5</iyy>
            <ixz>0</ixz>
            <iyz>0</iyz>
            <izz>1</izz>
          </inertia>
        </inertial>
        <collision name='collision'>
          <geometry>
            <cylinder>
              <radius>0.3175</radius>
              <length>0.2794</length>
            </cylinder>
          </geometry>
          <max_contacts>1</max_contacts>
          <surface>
            <friction>
              <ode>
                <mu>1</mu>
                <mu2>1</mu2>
                <fdir1>0 0 1</fdir1>
                <slip1>0</slip1>
                <slip2>0</slip2>
              </ode>
              <torsional>
                <ode/>
              </torsional>
            </friction>
            <contact>
              <ode>
                <min_depth>0.005</min_depth>
                <kp>1e+08</kp>
              </ode>
            </contact>
            <bounce/>
          </surface>
        </collision>
        <visual name='visual'>
          <pose frame=''>0 0 0 3.14159 -1.57079 3.14159</pose>
          <geometry>
            <mesh>
              <uri>model://rover/meshes/polaris.dae</uri>
              <scale>1.0037 0.8862 0.8862</scale>
              <submesh>
                <name>Wheel_Front_Right</name>
                <center>1</center>
              </submesh>
            </mesh>
          </geometry>
          <material>
            <script>
              <uri>model://rover/materials/scripts</uri>
              <uri>model://rover/materials/textures</uri>
              <name>PolarisXP900/Diffuse</name>
            </script>
          </material>
        </visual>
        <self_collide>0</self_collide>
        <kinematic>0</kinematic>
      </link>
      <link name='rear_left_wheel'>
        <pose frame=''>-0.99377 0.71562 0.34697 -1.52 0 0</pose>
        <inertial>
          <mass>12</mass>
          <inertia>
            <ixx>0.5</ixx>
            <ixy>0</ixy>
            <iyy>0.5</iyy>
            <ixz>0</ixz>
            <iyz>0</iyz>
            <izz>1</izz>
          </inertia>
        </inertial>
        <collision name='collision'>
          <geometry>
            <cylinder>
              <radius>0.3175</radius>
              <length>0.2794</length>
            </cylinder>
          </geometry>
          <max_contacts>1</max_contacts>
          <surface>
            <friction>
              <ode>
                <mu>1</mu>
                <mu2>1</mu2>
                <fdir1>0 0 1</fdir1>
                <slip1>0</slip1>
                <slip2>0</slip2>
              </ode>
              <torsional>
                <ode/>
              </torsional>
            </friction>
            <contact>
              <ode>
                <min_depth>0.005</min_depth>
                <kp>1e+08</kp>
              </ode>
            </contact>
            <bounce/>
          </surface>
        </collision>
        <visual name='visual'>
          <pose frame=''>0 0 0 3.14159 -1.57079 3.14159</pose>
          <geometry>
            <mesh>
              <uri>model://rover/meshes/polaris.dae</uri>
              <scale>1.0037 0.8862 0.8862</scale>
              <submesh>
                <name>Wheels_Rear_Left</name>
                <center>1</center>
              </submesh>
            </mesh>
          </geometry>
          <material>
            <script>
              <uri>model://rover/materials/scripts</uri>
              <uri>model://rover/materials/textures</uri>
              <name>PolarisXP900/Diffuse</name>
            </script>
          </material>
        </visual>
        <self_collide>0</self_collide>
        <kinematic>0</kinematic>
      </link>
      <link name='rear_right_wheel'>
        <pose frame=''>-0.99377 -0.71562 0.34697 1.52 -0 0</pose>
        <inertial>
          <mass>12</mass>
          <inertia>
            <ixx>0.5</ixx>
            <ixy>0</ixy>
            <iyy>0.5</iyy>
            <ixz>0</ixz>
            <iyz>0</iyz>
            <izz>1</izz>
          </inertia>
        </inertial>
        <collision name='collision'>
          <geometry>
            <cylinder>
              <radius>0.3175</radius>
              <length>0.2794</length>
            </cylinder>
          </geometry>
          <max_contacts>1</max_contacts>
          <surface>
            <friction>
              <ode>
                <mu>1</mu>
                <mu2>1</mu2>
                <fdir1>0 0 1</fdir1>
                <slip1>0</slip1>
                <slip2>0</slip2>
              </ode>
              <torsional>
                <ode/>
              </torsional>
            </friction>
            <contact>
              <ode>
                <min_depth>0.005</min_depth>
                <kp>1e+08</kp>
              </ode>
            </contact>
            <bounce/>
          </surface>
        </collision>
        <visual name='visual'>
          <pose frame=''>0 0 0 3.14159 -1.57079 3.14159</pose>
          <geometry>
            <mesh>
              <uri>model://rover/meshes/polaris.dae</uri>
              <scale>1.0037 0.8862 0.8862</scale>
              <submesh>
                <name>Wheels_Rear_Right</name>
                <center>1</center>
              </submesh>
            </mesh>
          </geometry>
          <material>
            <script>
              <uri>model://rover/materials/scripts</uri>
              <uri>model://rover/materials/textures</uri>
              <name>PolarisXP900/Diffuse</name>
            </script>
          </material>
        </visual>
        <self_collide>0</self_collide>
        <kinematic>0</kinematic>
      </link>
      <link name='front_right_wheel_steering_block'>
        <pose frame=''>1.20223 -0.5 0.35515 1.5708 -0 0</pose>
        <inertial>
          <mass>1</mass>
          <inertia>
            <ixx>0.01</ixx>
            <ixy>0</ixy>
            <iyy>0.01</iyy>
            <ixz>0</ixz>
            <iyz>0</iyz>
            <izz>0.01</izz>
          </inertia>
        </inertial>
        <collision name='collision'>
          <geometry>
            <cylinder>
              <radius>0.05</radius>
              <length>0.01</length>
            </cylinder>
          </geometry>
          <max_contacts>10</max_contacts>
          <surface>
            <contact>
              <ode/>
            </contact>
            <bounce/>
            <friction>
              <torsional>
                <ode/>
              </torsional>
              <ode/>
            </friction>
          </surface>
        </collision>
        <self_collide>0</self_collide>
        <kinematic>0</kinematic>
      </link>
      <link name='front_left_wheel_steering_block'>
        <pose frame=''>1.20223 0.5 0.35515 1.5708 -0 0</pose>
        <inertial>
          <mass>1</mass>
          <inertia>
            <ixx>0.01</ixx>
            <ixy>0</ixy>
            <iyy>0.01</iyy>
            <ixz>0</ixz>
            <iyz>0</iyz>
            <izz>0.01</izz>
          </inertia>
        </inertial>
        <collision name='collision'>
          <geometry>
            <cylinder>
              <radius>0.05</radius>
              <length>0.01</length>
            </cylinder>
          </geometry>
          <max_contacts>10</max_contacts>
          <surface>
            <contact>
              <ode/>
            </contact>
            <bounce/>
            <friction>
              <torsional>
                <ode/>
              </torsional>
              <ode/>
            </friction>
          </surface>
        </collision>
        <self_collide>0</self_collide>
        <kinematic>0</kinematic>
      </link>
      <joint name='front_left_steering_joint' type='revolute'>
        <child>front_left_wheel_steering_block</child>
        <parent>base_link</parent>
        <axis>
          <xyz>0 0 1</xyz>
          <limit>
            <lower>-0.7727</lower>
            <upper>0.7727</upper>
          </limit>
          <dynamics>
            <damping>50</damping>
            <spring_reference>0</spring_reference>
            <spring_stiffness>0</spring_stiffness>
          </dynamics>
          <use_parent_model_frame>1</use_parent_model_frame>
        </axis>
        <physics>
          <ode>
            <cfm_damping>1</cfm_damping>
            <limit>
              <cfm>0</cfm>
              <erp>0.9</erp>
            </limit>
          </ode>
        </physics>
      </joint>
      <joint name='front_left_wheel_joint' type='revolute'>
        <child>front_left_wheel</child>
        <parent>front_left_wheel_steering_block</parent>
        <axis>
          <xyz>0 1 0.05</xyz>
          <use_parent_model_frame>1</use_parent_model_frame>
          <limit>
            <lower>-1e+16</lower>
            <upper>1e+16</upper>
          </limit>
          <dynamics>
            <spring_reference>0</spring_reference>
            <spring_stiffness>0</spring_stiffness>
          </dynamics>
        </axis>
      </joint>
      <joint name='front_right_steering_joint' type='revolute'>
        <child>front_right_wheel_steering_block</child>
        <parent>base_link</parent>
        <axis>
          <xyz>0 0 1</xyz>
          <limit>
            <lower>-0.7727</lower>
            <upper>0.7727</upper>
          </limit>
          <dynamics>
            <damping>50</damping>
            <spring_reference>0</spring_reference>
            <spring_stiffness>0</spring_stiffness>
          </dynamics>
          <use_parent_model_frame>1</use_parent_model_frame>
        </axis>
        <physics>
          <ode>
            <cfm_damping>1</cfm_damping>
            <limit>
              <cfm>0</cfm>
              <erp>0.9</erp>
            </limit>
          </ode>
        </physics>
      </joint>
      <joint name='front_right_wheel_joint' type='revolute'>
        <child>front_right_wheel</child>
        <parent>front_right_wheel_steering_block</parent>
        <axis>
          <xyz>0 1 -0.05</xyz>
          <use_parent_model_frame>1</use_parent_model_frame>
          <limit>
            <lower>-1e+16</lower>
            <upper>1e+16</upper>
          </limit>
          <dynamics>
            <spring_reference>0</spring_reference>
            <spring_stiffness>0</spring_stiffness>
          </dynamics>
        </axis>
      </joint>
      <joint name='rear_left_wheel_joint' type='revolute'>
        <child>rear_left_wheel</child>
        <parent>base_link</parent>
        <axis>
          <xyz>0 1 0.05</xyz>
          <use_parent_model_frame>1</use_parent_model_frame>
          <limit>
            <lower>-1e+16</lower>
            <upper>1e+16</upper>
          </limit>
          <dynamics>
            <spring_reference>0</spring_reference>
            <spring_stiffness>0</spring_stiffness>
          </dynamics>
        </axis>
      </joint>
      <joint name='rear_right_wheel_joint' type='revolute'>
        <pose frame=''>0 0 -0.1 0 -0 0</pose>
        <child>rear_right_wheel</child>
        <parent>base_link</parent>
        <axis>
          <xyz>0 1 -0.05</xyz>
          <use_parent_model_frame>1</use_parent_model_frame>
          <limit>
            <lower>-1e+16</lower>
            <upper>1e+16</upper>
          </limit>
          <dynamics>
            <spring_reference>0</spring_reference>
            <spring_stiffness>0</spring_stiffness>
          </dynamics>
        </axis>
      </joint>
      <pose frame=''>12.6214 -65.7494 -3.50283 -0.008033 0.063183 -1.67898</pose>
    </model>
    <model name='washer'>
      <link name='link'>
        <pose frame=''>0 0 0.001 0 -0 0</pose>
        <inertial>
          <mass>0.0122</mass>
          <inertia>
            <ixx>1.08758e-06</ixx>
            <ixy>0</ixy>
            <ixz>0</ixz>
            <iyy>1.08758e-06</iyy>
            <iyz>0</iyz>
            <izz>2.16703e-06</izz>
          </inertia>
        </inertial>
        <collision name='collision'>
          <geometry>
            <mesh>
              <uri>model://washer/meshes/washer.dae</uri>
            </mesh>
          </geometry>
          <surface>
            <contact>
              <poissons_ratio>0.305</poissons_ratio>
              <elastic_modulus>2e+11</elastic_modulus>
              <ode>
                <kp>100000</kp>
                <kd>100</kd>
                <max_vel>100</max_vel>
                <min_depth>0.001</min_depth>
              </ode>
            </contact>
            <friction>
              <torsional>
                <coefficient>1</coefficient>
                <use_patch_radius>0</use_patch_radius>
                <surface_radius>0.01</surface_radius>
                <ode/>
              </torsional>
              <ode/>
            </friction>
            <bounce/>
          </surface>
          <max_contacts>10</max_contacts>
        </collision>
        <visual name='visual'>
          <geometry>
            <mesh>
              <uri>model://washer/meshes/washer.dae</uri>
            </mesh>
          </geometry>
          <material>
            <script>
              <uri>file://media/materials/scripts/gazebo.material</uri>
              <name>Gazebo/Grey</name>
            </script>
          </material>
        </visual>
        <self_collide>0</self_collide>
        <kinematic>0</kinematic>
      </link>
      <pose frame=''>84.79 -54.2511 17.8365 -0.09416 0.018284 -0.001123</pose>
    </model>
    <state world_name='default'>
      <sim_time>105 696000000</sim_time>
      <real_time>110 305147685</real_time>
      <wall_time>1591053184 851937410</wall_time>
      <iterations>26424</iterations>
      <model name='bishop-terrain'>
        <pose frame=''>23.6349 -18.1035 7.75309 0 -0 0</pose>
        <scale>1 1 1</scale>
        <link name='link'>
          <pose frame=''>23.6349 -18.1035 7.75309 0 -0 0</pose>
          <velocity>0 0 0 0 -0 0</velocity>
          <acceleration>0 0 0 0 -0 0</acceleration>
          <wrench>0 0 0 0 -0 0</wrench>
        </link>
      </model>
      <model name='cps_rover'>
        <pose frame=''>12.6214 -65.7494 -3.50283 -0.008033 0.063183 -1.67898</pose>
        <scale>1 1 1</scale>
        <link name='base_link'>
          <pose frame=''>12.6214 -65.7494 -3.50283 -0.008033 0.063183 -1.67898</pose>
          <velocity>0 0 0 0 -0 0</velocity>
          <acceleration>0 0 0 0 -0 0</acceleration>
          <wrench>0 0 0 0 -0 0</wrench>
        </link>
        <link name='front_left_wheel'>
          <pose frame=''>13.2037 -67.0412 -3.23821 -1.52803 0.063183 -1.67898</pose>
          <velocity>0 0 0 0 -0 0</velocity>
          <acceleration>0 0 0 0 -0 0</acceleration>
          <wrench>0 0 0 0 -0 0</wrench>
        </link>
        <link name='front_left_wheel_steering_block'>
          <pose frame=''>12.9894 -67.0186 -3.22832 1.56277 0.063183 -1.67898</pose>
          <velocity>0 0 0 0 -0 0</velocity>
          <acceleration>0 0 0 0 -0 0</acceleration>
          <wrench>0 0 0 0 -0 0</wrench>
        </link>
        <link name='front_right_wheel'>
          <pose frame=''>11.7808 -66.8874 -3.22674 1.51197 0.063183 -1.67898</pose>
          <velocity>0 0 0 0 -0 0</velocity>
          <acceleration>0 0 0 0 -0 0</acceleration>
          <wrench>0 0 0 0 -0 0</wrench>
        </link>
        <link name='front_right_wheel_steering_block'>
          <pose frame=''>11.9952 -66.9111 -3.2203 1.56277 0.063183 -1.67898</pose>
          <velocity>0 0 0 0 -0 0</velocity>
          <acceleration>0 0 0 0 -0 0</acceleration>
          <wrench>0 0 0 0 -0 0</wrench>
        </link>
        <link name='rear_left_wheel'>
          <pose frame=''>13.4403 -64.8624 -3.09955 -1.52803 0.063183 -1.67898</pose>
          <velocity>0 0 0 0 -0 0</velocity>
          <acceleration>0 0 0 0 -0 0</acceleration>
          <wrench>0 0 0 0 -0 0</wrench>
        </link>
        <link name='rear_right_wheel'>
          <pose frame=''>12.0174 -64.7086 -3.08808 1.51197 0.063183 -1.67898</pose>
          <velocity>0 0 0 0 -0 0</velocity>
          <acceleration>0 0 0 0 -0 0</acceleration>
          <wrench>0 0 0 0 -0 0</wrench>
        </link>
        <link name='rover/imu_link'>
          <pose frame=''>12.6214 -65.7494 -3.50283 -0.008033 0.063183 -1.67898</pose>
          <velocity>0 0 0 0 -0 0</velocity>
          <acceleration>0 0 0 0 -0 0</acceleration>
          <wrench>0 0 0 0 -0 0</wrench>
        </link>
      </model>
      <model name='pb-rock'>
        <pose frame=''>60.2074 -12.5043 18.7763 -2.03856 0.282061 -2.72179</pose>
        <scale>1 1 1</scale>
        <link name='link'>
        <pose frame=''>60.2074 -12.5043 18.7763 -2.03856 0.282061 -2.72179</pose>
          <velocity>0 0 0 0 -0 0</velocity>
          <acceleration>3.71643 0.165136 2.85221 -0.294547 -0.868305 0.11871</acceleration>
          <wrench>3.71643 0.165136 2.85221 0 -0 0</wrench>
        </link>
      </model>
      <model name='sample_probe'>
        <pose frame=''>40.3599 3.959 11.2109 0.121226 0.096102 0.164225</pose>
        <scale>1 1 1</scale>
        <link name='base_link'>
          <pose frame=''>40.3599 3.959 11.2109 0.121226 0.096102 0.164225</pose>
          <velocity>0.004001 -0.000835 0.006147 0.003412 0.043287 0.004749</velocity>
          <acceleration>4.07664 1.09513 5.69908 1.18525 -1.47992 -1.31641</acceleration>
          <wrench>0.407664 0.109513 0.569908 0 -0 0</wrench>
        </link>
        <link name='probe_camera_up'>
          <pose frame=''>40.3712 3.94862 11.3097 0.898251 -1.41634 -0.740094</pose>
          <velocity>0.008853 -0.001189 0.005573 -0.010996 0.054456 0.003178</velocity>
          <acceleration>8.99427 2.42819 5.36122 -2.51719 1.11933 -0.939289</acceleration>
          <wrench>0.134914 0.036423 0.080418 0 -0 0</wrench>
        </link>
      </model>
      <model name='washer'>
        <pose frame=''>84.79 -54.2511 17.8364 -0.091357 0.011984 -0.000436</pose>
        <scale>1 1 1</scale>
        <link name='link'>
          <pose frame=''>84.79 -54.251 17.8374 -0.091357 0.011984 -0.000436</pose>
          <velocity>0 0 0 0 -0 0</velocity>
          <acceleration>0 0 0 1.5e-05 -9e-06 1e-06</acceleration>
          <wrench>0 0 0 0 -0 0</wrench>
        </link>
      </model>
      <light name='sun'>
        <pose frame=''>0 0 8 0 -0 0</pose>
      </light>
    </state>
    <gui fullscreen='0'>
      <camera name='user_camera'>
        <pose frame=''>-7.11951 0.013965 1.61684 0 0.089796 -0.075791</pose>
        <view_controller>orbit</view_controller>
        <projection_type>perspective</projection_type>
      </camera>
    </gui>
    <model name='sample_probe'>
      <link name='base_link'>
        <inertial>
          <mass>0.1</mass>
          <inertia>
            <ixx>0.0004</ixx>
            <ixy>0</ixy>
            <ixz>0</ixz>
            <iyy>0.0004</iyy>
            <iyz>0</iyz>
            <izz>0.0005</izz>
          </inertia>
        </inertial>
        <self_collide>0</self_collide>
        <kinematic>0</kinematic>
        <velocity_decay/>
        <gravity>1</gravity>
        <visual name='visual'>
          <geometry>
            <cylinder>
              <radius>0.1</radius>
              <length>0.15</length>
            </cylinder>
          </geometry>
          <material>
            <ambient>0.1 0.1 0.1 1</ambient>
            <diffuse>1 0.1 0.2 1</diffuse>
            <specular>0 0 0 0</specular>
            <emissive>0 0 0 1</emissive>
          </material>
        </visual>
        <collision name='base_link_inertia_collision'>
          <geometry>
            <cylinder>
              <radius>0.1</radius>
              <length>0.15</length>
            </cylinder>
          </geometry>
          <max_contacts>10</max_contacts>
          <surface>
            <contact>
              <ode/>
            </contact>
            <bounce/>
            <friction>
              <torsional>
                <ode/>
              </torsional>
              <ode/>
            </friction>
          </surface>
        </collision>
      </link>
      <pose frame=''>-2.29391 -2.27848 0 1.57046 3.7e-05 -0.00352</pose>
      <link name='probe_camera_up'>
        <pose frame=''>-0 -0 0.1 -9.4e-05 -1.57079 -9.4e-05</pose>
        <inertial>
          <pose frame=''>0 0 0 0 -0 0</pose>
          <mass>0.015</mass>
          <inertia>
            <ixx>1e-06</ixx>
            <ixy>0</ixy>
            <ixz>0</ixz>
            <iyy>1e-06</iyy>
            <iyz>0</iyz>
            <izz>1e-06</izz>
          </inertia>
        </inertial>
        <self_collide>0</self_collide>
        <kinematic>0</kinematic>
        <sensor name='camera' type='camera'>
          <always_on>1</always_on>
          <update_rate>30</update_rate>
          <camera name='__default__'>
            <image>
              <width>640</width>
              <height>480</height>
            </image>
            <clip>
              <near>0.1</near>
              <far>100</far>
            </clip>
            <horizontal_fov>1.047</horizontal_fov>
          </camera>
          <plugin name='camera_plugin' filename='libgazebo_ros_camera.so'>
            <alwaysOn>true</alwaysOn>
            <imageTopicName>image_raw</imageTopicName>
            <cameraInfoTopicName>camera_info</cameraInfoTopicName>
            <updateRate>10.0</updateRate>
            <cameraName>probe_camera_up</cameraName>
            <frameName>probe_camera_up</frameName>
            <CxPrime>320.5</CxPrime>
            <Cx>320.5</Cx>
            <Cy>240.5</Cy>
            <hackBaseline>0</hackBaseline>
            <focalLength>1</focalLength>
            <distortionK1>0.0</distortionK1>
            <distortionK2>0.0</distortionK2>
            <distortionK3>0.0</distortionK3>
            <distortionT1>0.0</distortionT1>
            <distortionT2>0.0</distortionT2>
            <robotNamespace>/</robotNamespace>
          </plugin>
        </sensor>
        <visual name='visual'>
          <geometry>
            <box>
              <size>0.001 0.001 0.001</size>
            </box>
          </geometry>
          <pose frame=''>0 0 0 0 -0 0</pose>
          <cast_shadows>1</cast_shadows>
          <transparency>0</transparency>
          <material>
            <shader type='pixel'/>
          </material>
        </visual>
      </link>
      <joint name='probe_cam_joint_up' type='revolute'>
        <parent>base_link</parent>
        <child>probe_camera_up</child>
        <axis>
          <xyz>1 0 0</xyz>
          <use_parent_model_frame>1</use_parent_model_frame>
          <limit>
            <lower>0</lower>
            <upper>0</upper>
            <effort>0</effort>
            <velocity>0</velocity>
          </limit>
          <dynamics>
            <spring_reference>0</spring_reference>
            <spring_stiffness>0</spring_stiffness>
            <damping>0</damping>
            <friction>0</friction>
          </dynamics>
        </axis>
        <physics>
          <ode>
            <limit>
              <cfm>0</cfm>
              <erp>0.2</erp>
            </limit>
            <suspension>
              <cfm>0</cfm>
              <erp>0.2</erp>
            </suspension>
          </ode>
        </physics>
      </joint>
    </model>
    <model name='pb-rock'>
      <pose frame=''>0 0 1 0 -0 0</pose>
      <static>0</static>
      <link name='link'>
        <collision name='collision'>
          <geometry>
            <mesh>
              <uri>model://pb-rock/meshes/pb-rock.stl</uri>
            </mesh>
          </geometry>
          <max_contacts>10</max_contacts>
          <surface>
            <contact>
              <ode/>
            </contact>
            <bounce/>
            <friction>
              <torsional>
                <ode/>
              </torsional>
              <ode/>
            </friction>
          </surface>
        </collision>
        <visual name='visual'>
          <geometry>
            <mesh>
              <uri>model://pb-rock/meshes/pb-rock.stl</uri>
            </mesh>
          </geometry>
          <material>
            <ambient>0.1 0.1 0.1 1</ambient>
            <diffuse>0.8 0.5 0.01 1</diffuse>
            <specular>0 0 0 0</specular>
            <emissive>0 0 0 1</emissive>
          </material>
        </visual>
        <self_collide>0</self_collide>
        <inertial>
          <inertia>
            <ixx>1</ixx>
            <ixy>0</ixy>
            <ixz>0</ixz>
            <iyy>1</iyy>
            <iyz>0</iyz>
            <izz>1</izz>
          </inertia>
          <mass>100</mass>
        </inertial>
        <kinematic>0</kinematic>
      </link>
    </model>
  </world>
</sdf>
